<?xml version="1.0" encoding="utf-8"?>
<!-- =================================================================================== -->
<!-- |    This document was autogenerated by xacro from kuka_ex6.xacro                 | -->
<!-- |    EDITING THIS FILE BY HAND IS NOT RECOMMENDED                                 | -->
<!-- =================================================================================== -->
<robot name="kuka_ex6">
  <link name="binario">
    <visual>
      <geometry>
        <box size="0.05 0.05 2"/>
      </geometry>
      <origin rpy="1.55 0 0" xyz="0 0 0"/>
      <material name="yellow">
        <color rgba="0.8 0.8 0.0 1.0"/>
      </material>
    </visual>
    <collision>
      <geometry>
        <box size="0.05 0.05 2"/>
      </geometry>
      <origin rpy="1.55 0 0" xyz="0 0 0"/>
    </collision>
    <inertial>
      <mass value="1"/>
      <inertia ixx="1.0" ixy="0.0" ixz="0.0" iyy="1.0" iyz="0.0" izz="1.0"/>
    </inertial>
  </link>
  <joint name="joint0" type="prismatic">
    <parent link="binario"/>
    <child link="base_link"/>
    <origin xyz="0 0 0"/>
    <axis xyz="0 1 0"/>
    <limit effort="300" lower="-0.90" upper="0.90" velocity="1"/>
    <material name="yellow">
      <color rgba="0.8 0.8 0.0 1.0"/>
    </material>
    <dynamics damping="50" friction="1"/>
  </joint>
  <link name="base_link">
    <visual>
      <geometry>
        <cylinder length="0.2" radius="0.08"/>
      </geometry>
      <origin rpy="0 0 0" xyz="0 0 0.1"/>
      <material name="grey">
        <color rgba="0.4 0.4 0.4 1.0"/>
      </material>
    </visual>
    <collision>
      <geometry>
        <cylinder length="0.5" radius="0.08"/>
      </geometry>
      <origin rpy="0 0 0" xyz="0 0 0"/>
    </collision>
    <inertial>
      <mass value="1"/>
      <inertia ixx="1.0" ixy="0.0" ixz="0.0" iyy="1.0" iyz="0.0" izz="1.0"/>
    </inertial>
  </link>
  <joint name="joint1" type="revolute">
    <parent link="base_link"/>
    <child link="link1"/>
    <origin xyz="0 0 0.23"/>
    <axis xyz="0 0 1"/>
    <limit effort="176" lower="-2.96555555556" upper="2.96555555556" velocity="1.71"/>
    <material name="yellow">
      <color rgba="0.8 0.8 0.0 1.0"/>
    </material>
    <dynamics damping="50" friction="1"/>
  </joint>
  <link name="link1">
    <visual>
      <geometry>
        <cylinder length="0.1" radius="0.05"/>
      </geometry>
      <origin rpy="0 0 0.09" xyz="0 0 0"/>
      <material name="yellow">
        <color rgba="0.8 0.8 0.0 1.0"/>
      </material>
    </visual>
    <collision>
      <geometry>
        <cylinder length="0.1" radius="0.05"/>
      </geometry>
      <origin rpy="0 0 0.09" xyz="0 0 0"/>
    </collision>
    <inertial>
      <mass value="1"/>
      <inertia ixx="1.0" ixy="0.0" ixz="0.0" iyy="1.0" iyz="0.0" izz="1.0"/>
    </inertial>
  </link>
  <joint name="joint2" type="prismatic">
    <parent link="link1"/>
    <child link="link2"/>
    <origin xyz="0 0 0.1"/>
    <axis xyz="0 0 1"/>
    <limit effort="300" lower="-0.08" upper="0.08" velocity="1.71"/>
    <material name="yellow">
      <color rgba="0.8 0.8 0.0 1.0"/>
    </material>
    <dynamics damping="50" friction="1"/>
  </joint>
  <link name="link2">
    <visual>
      <geometry>
        <cylinder length="0.2" radius="0.03"/>
      </geometry>
      <origin rpy="0 0 0" xyz="0 0 0"/>
      <material name="yellow">
        <color rgba="0.8 0.8 0.0 1.0"/>
      </material>
    </visual>
    <collision>
      <geometry>
        <cylinder length="0.2" radius="0.03"/>
      </geometry>
      <origin rpy="0 0 0" xyz="0 0 0"/>
    </collision>
    <inertial>
      <mass value="1"/>
      <inertia ixx="1.0" ixy="0.0" ixz="0.0" iyy="1.0" iyz="0.0" izz="1.0"/>
    </inertial>
  </link>
  <joint name="joint3" type="revolute">
    <parent link="link2"/>
    <child link="link3"/>
    <origin xyz="0 -0.05 0.12"/>
    <axis xyz="0 -1 0"/>
    <limit effort="110" lower="-2.09333333333" upper="1.90" velocity="2.26"/>
    <material name="yellow">
      <color rgba="0.8 0.8 0.0 1.0"/>
    </material>
    <dynamics damping="50" friction="1"/>
  </joint>
  <link name="link3">
    <visual>
      <geometry>
        <cylinder length="0.2" radius="0.03"/>
      </geometry>
      <origin rpy="1.5 0 0" xyz="0 0 0"/>
      <material name="yellow">
        <color rgba="0.8 0.8 0.0 1.0"/>
      </material>
    </visual>
    <collision>
      <geometry>
        <cylinder length="0.2" radius="0.03"/>
      </geometry>
      <origin rpy="1.5 0 0" xyz="0 0 0"/>
    </collision>
    <inertial>
      <mass value="1"/>
      <inertia ixx="1.0" ixy="0.0" ixz="0.0" iyy="1.0" iyz="0.0" izz="1.0"/>
    </inertial>
  </link>
  <joint name="joint4" type="revolute">
    <parent link="link3"/>
    <child link="link4"/>
    <origin xyz="0 -0.05 0.1"/>
    <axis xyz="0 0 1"/>
    <limit effort="110" lower="-2.96555555556" upper="2.96555555556" velocity="2.44"/>
    <material name="yellow">
      <color rgba="0.8 0.8 0.0 1.0"/>
    </material>
    <dynamics damping="50" friction="1"/>
  </joint>
  <link name="link4">
    <visual>
      <geometry>
        <cylinder length="0.2" radius="0.03"/>
      </geometry>
      <origin rpy="0 0 0" xyz="0 0 0"/>
      <material name="yellow">
        <color rgba="0.8 0.8 0.0 1.0"/>
      </material>
    </visual>
    <collision>
      <geometry>
        <cylinder length="0.2" radius="0.03"/>
      </geometry>
      <origin rpy="0 0 0" xyz="0 0 0"/>
    </collision>
    <inertial>
      <mass value="1"/>
      <inertia ixx="1.0" ixy="0.0" ixz="0.0" iyy="1.0" iyz="0.0" izz="1.0"/>
    </inertial>
  </link>
  <joint name="joint5" type="revolute">
    <parent link="link4"/>
    <child link="link5"/>
    <origin xyz="0 0.08 0.07"/>
    <axis xyz="1 0 0"/>
    <limit effort="40" lower="-0.03" upper="0.28" velocity="3.14"/>
    <material name="yellow">
      <color rgba="0.8 0.8 0.0 1.0"/>
    </material>
    <dynamics damping="50" friction="1"/>
  </joint>
  <link name="link5">
    <visual>
      <geometry>
        <cylinder length="0.2" radius="0.03"/>
      </geometry>
      <origin rpy="1.5 0 0" xyz="0 0 0"/>
      <material name="yellow">
        <color rgba="0.8 0.8 0.0 1.0"/>
      </material>
    </visual>
    <collision>
      <geometry>
        <cylinder length="0.2" radius="0.03"/>
      </geometry>
      <origin rpy="1.5 0 0" xyz="0 0 0"/>
    </collision>
    <inertial>
      <mass value="1"/>
      <inertia ixx="1.0" ixy="0.0" ixz="0.0" iyy="1.0" iyz="0.0" izz="1.0"/>
    </inertial>
  </link>
  <joint name="joint6" type="prismatic">
    <parent link="link5"/>
    <child link="end_effector"/>
    <origin xyz="0 0.08 0"/>
    <axis xyz="0 1 0"/>
    <limit effort="40" lower="-0.02" upper="0.03" velocity="3.14"/>
    <material name="yellow">
      <color rgba="0.8 0.8 0.0 1.0"/>
    </material>
    <dynamics damping="50" friction="1"/>
  </joint>
  <link name="end_effector">
    <visual>
      <geometry>
        <cylinder length="0.1" radius="0.02"/>
      </geometry>
      <origin rpy="1.5 0 0" xyz="0 0 0"/>
      <material name="blue">
        <color rgba="0.0 0.0 1.0 1.0"/>
      </material>
    </visual>
    <collision>
      <geometry>
        <cylinder length="0.1" radius="0.02"/>
      </geometry>
      <origin rpy="1.5 0 0" xyz="0 0 0"/>
    </collision>
    <inertial>
      <mass value="0.5"/>
      <inertia ixx="1.0" ixy="0.0" ixz="0.0" iyy="1.0" iyz="0.0" izz="1.0"/>
    </inertial>
  </link>
</robot>

